Workbook

Sheet Synthesis_TestCase
A1: Your Company LOGO | B1: Project Name: | E1: Test Designed by:
B2: Module Name: | E2: Test Designed date:
B3: Release Version: | E3: Test Executed by:
E4: Test Execution date:
A6: Pre-condition
A7: Dependencies:
A8: Test Priority
A10: TestCase | B10: Test title/scenario | C10: Pre-condition | D10: Test Sumary | E10: Test Step | F10: Test Data | G10: Expected Result | H10: Actual Result | I10: Status | J10: Notes | K10: Test scripts
A11: QLD_01 | B11: Quản lý đơn hàng [Admin] | C11: Có đơn hàng trong cơ sở dữ liệu | D11: Hiển thị đơn hàng đúng dữ liệu trên giao diện | E11: 1. Truy cập http://localhost:4200/login 2. Đăng nhập bằng tài khoản admin 3. Điều hướng đến http://localhost:4200/manages/order/order-list 4.Kiểm tra danh sách đơn hàng hiển thị | G11: [4].Hiện thị đúng thông tin đơn hàng | H11: [4].Hiện thị thông tin đơn hàng đúng với cơ sở dữ liệu | I11: Pass | K11: HienThiDonHang_Test.cs
A12: QLD_02 | C12: Có đơn hàng trong cơ sở dữ liệu | D12: Kiểm tra thông tin đơn hàng hiển thị có đúng với dữ liệu trong hệ thống | E12: 1. Truy cập http://localhost:4200/login 2. Đăng nhập bằng tài khoản admin 3. Điều hướng đến http://localhost:4200/manages/order/order-list 4. Tìm đơn hàng theo ID. 5. Nhấn nút "Xem chi tiết". | F12: ID Đơn hàng: 8 Tên khách hàng: Nguyễn Thị Minh Tâm Địa chỉ: Lý Thường Kiệt, P9, Quận Tân Bình, TPHCM Tổng giá trị: 1,800,000 Trạng thái: Đã giao hàng | G12: [3]. Hiện thị chi tiết đơn hàng | H12: [4].Hiện thị thông tin đơn hàng đúng với cơ sở dữ liệu | I12: Pass | K12: ChiTietDonHang_Test.cs
A13: QLD_03 | C13: Có đơn hàng bị lỗi trong cơ sở dữ liệu | D13: Xem chi tiết đơn hàng không có thông tin | E13: 1. Truy cập http://localhost:4200/login 2. Đăng nhập bằng tài khoản admin 3. Điều hướng đến http://localhost:4200/manages/order/order-list 4. Tìm đơn hàng theo ID. 5. Nhấn nút "Xem chi tiết". | F13: ID Đơn hàng: 11 Tên khách hàng: Nguyễn Ngọc Bảo Trâm Địa chỉ:123 Lê Lợi, Quận 1, TP. Hồ Chí Minh Tổng giá trị: 0 Trạng thái: Đang chờ | G13: [5]. Hiện thị thông báo "Không tìm thấy chi tiết đơn hàng" | H13: [4].Không tim thấy thông tin đơn hàng | I13: Pass | K13: ChiTietDonHang_Test.cs
A14: QLD_04 | C14: Có đơn hàng đang chờ | D14: Thay đổi trạng thái đơn hàng đang chờ thành đang xử lí | E14: 1. Truy cập http://localhost:4200/login 2. Đăng nhập bằng tài khoản admin 3. Điều hướng đến http://localhost:4200/manages/order/order-list 4. Nhấn vào xem chi tiết đơn hàng đang ở trạng thái đang chờ 5. Nhấn nút Duyệt 6. Nhấn nút Thực hiện 7. Truy cập http://localhost:4300/home | F14: ID Đơn hàng: 8 Trạng thái hiện tại: Đang chờ | G14: [5]. Thông báo "Bạn có muốn Duyệt đơn hàng này không?" Hiện lên [6]. Hiện thị thông báo cập nhật đã duyệt đơn hàng thành công và thấy trạng thái đơn hàng đã chuyển thành đang xử lý | H14: [5]. Hiện lên bảng thông báo xác nhận [6]Hiện thông báo đã cập nhật thành công | I14: =ThayDoiTrangThai_DataTest!E2 | K14: ThayDoiTrangThai_Test.cs
A15: QLD_05 | C15: Có đơn hàng đang chờ | D15: Thay đổi trạng thái đơn hàng đang chờ thành hủy | E15: 1. Truy cập http://localhost:4200/login 2. Đăng nhập bằng tài khoản admin 3. Điều hướng đến http://localhost:4200/manages/order/order-list 4. Nhấn vào xem chi tiết đơn hàng đang ở trạng thái đang chờ 5. Nhấn nút Hủy 6. Nhấn nút Thực hiện | F15: ID Đơn hàng: 8 Trạng thái hiện tại: Đang chờ | G15: [5]. Thông báo "Bạn có muốn Hủy đơn hàng đơn hàng này không?" Hiện lên [6]. Hiện thị thông báo cập nhật đã hủy đơn hàng thành công và thấy trạng thái đơn hàng đã chuyển thành đã hủy | H15: [5]. Hiện lên bảng thông báo xác nhận [6]Hiện thông báo đã cập nhật thành công | I15: =ThayDoiTrangThai_DataTest!E3 | K15: ThayDoiTrangThai_Test.cs
A16: QLD_06 | C16: Có đơn hàng đang xử lý | D16: Thay đổi trạng thái đơn hàng đang xử lý thành chuyển hàng cho vận chuyển | E16: 1. Truy cập http://localhost:4200/login 2. Đăng nhập bằng tài khoản admin 3. Điều hướng đến http://localhost:4200/manages/order/order-list 4. Nhấn vào xem chi tiết đơn hàng đang ở trạng thái đang xử lý 5. Nhấn nút Chuyển hàng cho shipper 6. Nhấn nút Thực hiện | F16: ID Đơn hàng: 8 Trạng thái hiện tại: Đang xử lý | G16: [5]. Thông báo "Bạn có muốn chuyển hàng cho vận chuyển này không?" Hiện lên [6]. Hiện thị thông báo cập nhật đã chuyển sang shipper thành công và thấy trạng thái đơn hàng đã chuyển sang bộ phận vận chuyển | H16: [5]. Hiện lên bảng thông báo xác nhận [6]Hiện thông báo đã cập nhật thành công | I16: =ThayDoiTrangThai_DataTest!E4 | K16: ThayDoiTrangThai_Test.cs
A17: QLD_07 | C17: Có đơn hàng đang xử lý | D17: Thay đổi trạng thái đơn hàng đang xử lý thành hủy | E17: 1. Truy cập http://localhost:4200/login 2. Đăng nhập bằng tài khoản admin 3. Điều hướng đến http://localhost:4200/manages/order/order-list 4. Nhấn vào xem chi tiết đơn hàng đang ở trạng thái đang xử lý 5. Nhấn nút Hủy 6. Nhấn nút Thực hiện | F17: ID Đơn hàng: 8 Trạng thái hiện tại: Đang xử lý | G17: [5]. Thông báo "Bạn có muốn Hủy đơn hàng đơn hàng này không?" Hiện lên [6]. Hiện thị thông báo cập nhật đã hủy đơn hàng thành công và thấy trạng thái đơn hàng đã chuyển thành đã hủy | H17: [5]. Hiện lên bảng thông báo xác nhận [6]Hiện thông báo đã cập nhật thành công | I17: =ThayDoiTrangThai_DataTest!E5 | K17: ThayDoiTrangThai_Test.cs
A18: QLD_08 | C18: Có đơn hàng đang chuyển hàng cho vận chuyển | D18: Thay đổi trạng thái Chuyển hàng cho vận chuyển thành đã giao hàng | E18: 1. Truy cập http://localhost:4200/login 2. Đăng nhập bằng tài khoản admin 3. Điều hướng đến http://localhost:4200/manages/order/order-list 4. Nhấn vào xem chi tiết đơn hàng đang ở trạng thái đang chuyển hàng cho vận chuyển 5. Nhấn nút Giao hàng thành công 6. Nhấn nút Thực hiện | F18: ID Đơn hàng: 8 Trạng thái hiện tại: Đang chuyển hàng cho vận chuyển | G18: [5]. Thông báo "Bạn có muốn Hoàn thành đơn hàng này không?" Hiện lên [6]. Hiện thị thông báo "Đã Hoàn thành đơn hàng thành công thành trạng thái." | H18: [5]. Hiện lên bảng thông báo xác nhận [6]Hiện thông báo đã cập nhật thành công | I18: =ThayDoiTrangThai_DataTest!E6 | K18: ThayDoiTrangThai_Test.cs
A19: QLD_09 | C19: Có đơn hàng ở trạng thái đã giao hàng | D19: Thay đổi trạng thái đã giao hàng thành giao hàng hủy | E19: 1. Truy cập http://localhost:4200/login 2. Đăng nhập bằng tài khoản admin 3. Điều hướng đến http://localhost:4200/manages/order/order-list 4. Nhấn vào xem chi tiết đơn hàng đang ở trạng thái đã giao hàng 5. Nhấn nút Hủy 6. Nhấn nút Thực hiện | F19: ID Đơn hàng: 8 Trạng thái hiện tại: Đã giao hàng | G19: [5]. Thông báo "Bạn có muốn Hủy đơn hàng đơn hàng này không?" Hiện lên [6]. Hiện thị thông báo cập nhật đã hủy đơn hàng thành công và thấy trạng thái đơn hàng đã chuyển thành đã hủy | H19: [5]. Hiện lên bảng thông báo xác nhận [6]Hiện thông báo đã cập nhật thành công | I19: =ThayDoiTrangThai_DataTest!E7 | K19: ThayDoiTrangThai_Test.cs
A20: QLD_10 | C20: Có đơn hàng đang chuyển hàng cho vận chuyển | D20: Thay đổi trạng thái Chuyển hàng cho vận chuyển thành giao hàng hủy | E20: 1. Truy cập http://localhost:4200/login 2. Đăng nhập bằng tài khoản admin 3. Điều hướng đến http://localhost:4200/manages/order/order-list 4. Nhấn vào xem chi tiết đơn hàng đang ở trạng thái đang chuyển hàng cho vận chuyển 5. Nhấn nút Hủy 6. Nhấn nút Thực hiện | F20: ID Đơn hàng: 8 Trạng thái hiện tại: Đang chuyển hàng cho vận chuyển | G20: [5]. Thông báo "Bạn có muốn Hủy đơn hàng đơn hàng này không?" Hiện lên [6]. Hiện thị thông báo cập nhật đã hủy đơn hàng thành công và thấy trạng thái đơn hàng đã chuyển thành đã hủy | H20: [5]. Hiện lên bảng thông báo xác nhận [6]Hiện thông báo đã cập nhật thành công | I20: =ThayDoiTrangThai_DataTest!E8 | K20: ThayDoiTrangThai_Test.cs
A21: TK_01 | B21: Thông kê [Admin] | C21: Đã có đơn hàng trong cơ sở dữ liệu | D21: Xem tổng số đơn hàng | E21: 1. Truy cập http://localhost:4200/login 2. Đăng nhập bằng tài khoản admin 3. Nhấn vào "Danh sách đơn hàng " 4. Nhấn vào "Danh thu " 5.Kiểm tra tổng đơn hàng | G21: [3].Hiển thị tất cả đơn hàng [5]. Hiển thị tổng đơn hàng | H21: [5].Hiện thị đúng số tổng đơn hàng trong cơ sở dữ liệu | I21: =ThongKe_Chart_DataTest!E2 | K21: ThongKe_Test.cs
A22: TK_02 | C22: Đã có sản phẩm trong cơ sở dữ liệu | D22: Xem tổng số sản phẩm | E22: 1. Truy cập http://localhost:4200/login 2. Đăng nhập bằng tài khoản admin 3. Nhấn vào "Danh sách cây " 4. Nhấn vào "Danh thu " 5.Kiểm tra tổng đơn hàng | G22: [3].Hiển thị tất cả sảm phẩm cây [5]. Hiển thị tổng đơn hàng | H22: [5].Hiện thị đúng số tổng sản phẩm trong cơ sở dữ liệu | I22: =ThongKe_Chart_DataTest!E2 | K22: ThongKe_Test.cs
A23: TK_03 | C23: Đã có khách hàng trong cơ sở dữ liệu | D23: Xem tổng số khách hàng | E23: 1. Truy cập http://localhost:4200/login 2. Đăng nhập bằng tài khoản admin 3. Nhấn vào "Danh sách khách hàng " 4. Nhấn vào "Danh thu " 5.Kiểm tra tổng đơn hàng | G23: [3].Hiển thị tất cả khách hàng [5]. Hiển thị tổng đơn hàng | H23: [5].Hiện thị đúng số tổng khách hàng trong cơ sở dữ liệu | I23: =ThongKe_Chart_DataTest!E2 | K23: ThongKe_Test.cs
A24: TK_04 | C24: Đã có đánh giá trong cơ sở dữ liệu | D24: Xem tổng số đánh giá | E24: 1. Truy cập http://localhost:4200/login 2. Đăng nhập bằng tài khoản admin 3. Nhấn vào "Danh sách đánh giá" 4. Nhấn vào "Danh thu " 5.Kiểm tra tổng đơn hàng | G24: [3].Hiển thị tất cả đánh giá [5]. Hiển thị tổng đơn hàng | H24: [5].Hiện thị đúng số tổng đánh giá trong cơ sở dữ liệu | I24: =ThongKe_Chart_DataTest!E2 | K24: ThongKe_Test.cs
A25: ĐN_01 | B25: Đăng nhập [Admin] | C25: Tài khoản phải tồn tại | D25: Đăng nhập vào trang quản trị bằng Email, Mật Khẩu chính xác | E25: 1. Truy cập http://localhost:4200/login 2. Nhập Email 3. Nhập Mật khẩu 4. Nhấn vào "Login " | F25: Email: minhtam39@gmail.com Mật khẩu: YourSecurePassword | G25: [4] Thông báo "👋 Welcome, Minh Tâm! Bạn đã đăng nhập thành công! 🎉" | H25: [4].Thông báo đăng nhập thành công vào trang quản trị | I25: =LogIn_DataTest!F2 | K25: Login_Test.cs
A26: ĐN_02 | C26: Tài khoản không tồn tại | D26: Đăng nhập vào trang quản trị bằng Email, Mật Khẩu không chính xác | E26: 1. Truy cập http://localhost:4200/login 2. Nhập Email 3. Nhập Mật khẩu 4. Nhấn vào "Login " | F26: Email: tame@gmail.com Mật khẩu: 1234 | G26: [4] Thông báo "Sai tên tài khoản hoặc mật khẩu" | H26: [4].Thông báo "Tài Khoản Không Tồn Tại" | I26: =LogIn_DataTest!F3 | K26: Login_Test.cs
A27: ĐN_03 | C27: Tài khoản không tồn tại | D27: Đăng nhập vào trang quản trị bằng Email không chính xác | E27: 1. Truy cập http://localhost:4200/login 2. Nhập Email 3. Nhập Mật khẩu 4. Nhấn vào "Login " | F27: Email: minhtam Mật khẩu: 12356 | G27: [4] Thông báo "Invalid email format" | H27: [4].Thông báo " Email này không đúng định dạng" | I27: =LogIn_DataTest!F4 | K27: Login_Test.cs
A28: ĐN_04 | C28: Tài khoản không tồn tại | D28: Đăng nhập vào trang quản trị bằng Mật Khẩu không chính xác | E28: 1. Truy cập http://localhost:4200/login 2. Nhập Email 3. Nhập Mật khẩu 4. Nhấn vào "Login " | F28: Email: minhtam@gmail.com Mật khẩu: minhtam | G28: [4] Thông báo "Sai tên tài khoản hoặc mật khẩu" | H28: [4].Thông báo " mật khẩu không chính xác" | I28: =LogIn_DataTest!F5 | K28: Login_Test.cs
A29: ĐN_05 | C29: Tài khoản không tồn tại | D29: Đăng nhập vào trang quản trị bằng Email, Mật Khẩu để trống | E29: 1. Truy cập http://localhost:4200/login 2. Nhập Email 3. Nhập Mật khẩu 4. Nhấn vào "Login " | F29: Email: Mật khẩu: | G29: [4] Thông báo "Invalid email format" và "Password is required" | H29: [4].Thông báo " Email và Mật Khẩu không được để trống" | I29: =LogIn_DataTest!F6 | K29: Login_Test.cs
A30: ĐN_06 | C30: Tài khoản không tồn tại | D30: Đăng nhập vào trang quản trị bằng với Email chứa kí tự đặc biệt | E30: 1. Truy cập http://localhost:4200/login 2. Nhập Email 3. Nhập Mật khẩu 4. Nhấn vào "Login " | F30: Email: minhtam!!@gmail.com Mật khẩu: YourSecurePassword | G30: [4] Thông báo "Sai tên tài khoản hoặc mật khẩu" | H30: [4].Thông báo " Email này không đúng định dạng" | I30: =LogIn_DataTest!F7 | K30: Login_Test.cs
A31: ĐN_07 | C31: Tài khoản không tồn tại | D31: Đăng nhập vào trang quản trị bằng với Mật Khẩu chứa kí tự đặc biệt | E31: 1. Truy cập http://localhost:4200/login 2. Nhập Email 3. Nhập Mật khẩu 4. Nhấn vào "Login " | F31: Email: minhtam@gmail.com Mật khẩu: YourSecureP___assword | G31: [4] Thông báo "Sai tên tài khoản hoặc mật khẩu" | H31: [4].Thông báo đăng nhập thành công vào trang quản trị | I31: =LogIn_DataTest!F8 | K31: Login_Test.cs
A32: ĐN_08 | C32: Tài khoản không tồn tại | D32: Đăng nhập với Email, Mật Khẩu chứa khoảng trắng | E32: 1. Truy cập http://localhost:4200/login 2. Nhập Email 3. Nhập Mật khẩu 4. Nhấn vào "Login " | F32: Email: minhta m@gmail.com Mật khẩu: YourSe curePassword | G32: [4] Thông báo "Invalid email format" | H32: [4].Thông báo " Email này không đúng định dạng" | I32: =LogIn_DataTest!F9 | K32: Login_Test.cs

Sheet QLDH_Intergrated_TestCase
A1: No. | B1: Test Case ID | C1: Test Objective | D1: Pre-conditions | E1: Step # | F1: Step Action | G1: Test Data | H1: Expected Result
A2: 1 | B2: TC_IN_01 | C2: Kiểm tra đơn hàng được thay đổi trang thái có thay đổi phía web người dùng không(đang chờ --> đang xử lí) | D2: Đăng nhập thành công vào module của khách hàng | E2: 1 | F2: Đăng nhập vào web với vai trò của admin | G2: Đơn hàng có trạng thái đang chờ | H2: Hệ thống hiển thị trang chủ của admin
D3: Đăng nhập thành công vào module của admin | E3: 2 | F3: Di chuyển qua trang quản lí đơn hàng
E4: 3 | F4: Chọn đơn hàng có trang thái đang chờ | H4: Hệ thống hiển thị thông tin đơn hàng đó
E5: 4 | F5: Thay đổi trạng thái từ đang chờ thành đang xử lý | H5: Đơn hàng thay đổi trạng thái thành công
E7: 5 | F7: Truy cập vào trang web người dùng và đăng nhập vào tài khoảng có đơn hàng đang test | H7: Hệ thống hiển thị trang web người dùng
E8: 6 | F8: Vào phần quản lí đơn hàng | H8: Hệ thống hiển thị đơn hàng
E9: 7 | F9: Kiểm tra xem trạng thái đã đổi thành đang xử lí chưa | H9: Hệ thống hiển thị trạng thái là đang xử lí
A10: 2 | B10: TC_IN_02 | C10: Kiểm tra đơn hàng được thay đổi trang thái có thay đổi phía web người dùng không(đang chờ --> hủy) | D10: Đăng nhập thành công vào module của khách hàng | E10: 1 | F10: Đăng nhập vào web với vai trò của admin | G10: Đơn hàng có trạng thái đang chờ | H10: Hệ thống hiển thị trang chủ của admin
D11: Đăng nhập thành công vào module của admin | E11: 2 | F11: Di chuyển qua trang quản lí đơn hàng
E12: 3 | F12: Chọn đơn hàng có trang thái đang chờ | H12: Hệ thống hiển thị thông tin đơn hàng đó
E13: 4 | F13: Thay đổi trạng thái từ đang chờ thành hủy đơn | H13: Đơn hàng thay đổi trạng thái thành công
E14: 9.0684932
E15: 5 | F15: Truy cập vào trang web người dùng và đăng nhập vào tài khoảng có đơn hàng đang test | H15: Hệ thống hiển thị trang web người dùng
E16: 6 | F16: Vào phần quản lí đơn hàng | H16: Hệ thống hiển thị đơn hàng
E17: 7 | F17: Kiểm tra xem trạng thái đã đổi thành hủy chưa | H17: Hệ thống hiển thị trạng thái là đang xử lí
A18: 3 | B18: TC_IN_03 | C18: Kiểm tra đơn hàng được thay đổi trang thái có thay đổi phía web người dùng không(đang xử lí --> Chuyển hàng cho vẩn chuyển) | D18: Đăng nhập thành công vào module của khách hàng | E18: 1 | F18: Đăng nhập vào web với vai trò của admin | G18: Đơn hàng có trạng thái đang xử lí | H18: Hệ thống hiển thị trang chủ của admin
D19: Đăng nhập thành công vào module của admin | E19: 2 | F19: Di chuyển qua trang quản lí đơn hàng
E20: 3 | F20: Chọn đơn hàng có trang thái đang xử lí | H20: Hệ thống hiển thị thông tin đơn hàng đó
E21: 4 | F21: Thay đổi trạng thái từ đang xử lí thành Chuyển hàng cho vẩn chuyển | H21: Đơn hàng thay đổi trạng thái thành công
E22: 14.465753
E23: 5 | F23: Truy cập vào trang web người dùng và đăng nhập vào tài khoảng có đơn hàng đang test | H23: Hệ thống hiển thị trang web người dùng
E24: 6 | F24: Vào phần quản lí đơn hàng | H24: Hệ thống hiển thị đơn hàng
E25: 7 | F25: Kiểm tra xem trạng thái đã đổi thành Chuyển hàng cho vận chuyển chưa | H25: Hệ thống hiển thị trạng thái là đang xử lí
A26: 4 | B26: TC_IN_04 | C26: Kiểm tra đơn hàng được thay đổi trang thái có thay đổi phía web người dùng không(Đang xử lí --> Hủy) | D26: Đăng nhập thành công vào module của khách hàng | E26: 1 | F26: Đăng nhập vào web với vai trò của admin | G26: Đơn hàng có trạng thái đang xử lí | H26: Hệ thống hiển thị trang chủ của admin
D27: Đăng nhập thành công vào module của admin | E27: 2 | F27: Di chuyển qua trang quản lí đơn hàng
E28: 3 | F28: Chọn đơn hàng có trang thái Đang xử lí | H28: Hệ thống hiển thị thông tin đơn hàng đó
E29: 4 | F29: Thay đổi trạng thái từ đang xử lí thành hủy | H29: Đơn hàng thay đổi trạng thái thành công
E30: 19.863014
E31: 5 | F31: Truy cập vào trang web người dùng và đăng nhập vào tài khoảng có đơn hàng đang test | H31: Hệ thống hiển thị trang web người dùng
E32: 6 | F32: Vào phần quản lí đơn hàng | H32: Hệ thống hiển thị đơn hàng
E33: 7 | F33: Kiểm tra xem trạng thái đã đổi thành hủy chưa | H33: Hệ thống hiển thị trạng thái là đang xử lí
A34: 5 | B34: TC_IN_05 | C34: Kiểm tra đơn hàng được thay đổi trang thái có thay đổi phía web người dùng không(Chuyển hàng cho vẩn chuyển --> Giao hàng thành công) | D34: Đăng nhập thành công vào module của khách hàng | E34: 1 | F34: Đăng nhập vào web với vai trò của admin | G34: Đơn hàng có trạng thái Chuyển đơn hàng cho vận chuyển | H34: Hệ thống hiển thị trang chủ của admin
D35: Đăng nhập thành công vào module của admin | E35: 2 | F35: Di chuyển qua trang quản lí đơn hàng
E36: 3 | F36: Chọn đơn hàng có trang thái Chuyển hàng cho vẩn chuyển | H36: Hệ thống hiển thị thông tin đơn hàng đó
E37: 4 | F37: Thay đổi trạng thái từ Chuyển đơn hàng cho vẩn chuyển thành Giao thành công | H37: Đơn hàng thay đổi trạng thái thành công
E38: 19.863014
E39: 5 | F39: Truy cập vào trang web người dùng và đăng nhập vào tài khoảng có đơn hàng đang test | H39: Hệ thống hiển thị trang web người dùng
E40: 6 | F40: Vào phần quản lí đơn hàng | H40: Hệ thống hiển thị đơn hàng
E41: 7 | F41: Kiểm tra xem trạng thái đã đổi thành Giao thành công chưa | H41: Hệ thống hiển thị trạng thái là đang xử lí
...

Sheet QLDH_ChiTietDonHang_DataTest
A1: Id TestCase | B1: ID Đơn hàng | C1: Tên khách hàng | D1: Địa chỉ | E1: Tổng giá trị | F1: Trạng thái | G1: Result
A2: =Synthesis_TestCase!A12 | B2: 8 | C2: Nguyễn Thị Minh Tâm | D2: Lý Thường Kiệt, P9, Quận Tân Bình, TPHCM | E2: ₫1,800,000 | F2: Đã giao hàng | G2: Pass
A3: =Synthesis_TestCase!A13 | B3: 11 | C3: Nguyễn Ngọc Bảo Trâm | D3: 123 Lê Lợi, Quận 1, TP. Hồ Chí Minh | E3: 0 | F3: Đang chờ | G3: Fail

Sheet ThongKe_Chart_DataTest
A1: Tổng Đơn Hàng | B1: Tổng Sản Phẩm | C1: Tổng Khách Hàng | D1: Tổng Đánh Giá | E1: Result
A2: 34 | B2: 24 | C2: 18 | D2: 9 | E2: Pass

Sheet ThayDoiTrangThai_DataTest
A1: Id TestCase | B1: ID Đơn hàng | C1: Trạng thái hiện tại | D1: Trạng thái mong muốn | E1: Result
A2: =Synthesis_TestCase!A14 | B2: 17 | C2: Đang chờ | D2: Đang xử lý | E2: Fail
A3: =Synthesis_TestCase!A15 | B3: 18 | C3: Đang chờ | D3: Hủy | E3: Fail
A4: =Synthesis_TestCase!A16 | B4: 21 | C4: Đang xử lý | D4: Chuyển hàng cho vận chuyển | E4: Fail
A5: =Synthesis_TestCase!A17 | B5: 76 | C5: Đang xử lý | D5: Hủy | E5: Fail
A6: =Synthesis_TestCase!A18 | B6: 77 | C6: Chuyển hàng cho vận chuyển | D6: Đã giao hàng | E6: Fail
A7: =Synthesis_TestCase!A19 | B7: 19 | C7: Đã giao hàng | D7: Hủy | E7: Fail
A8: =Synthesis_TestCase!A20 | B8: 53 | C8: Chuyển hàng cho vận chuyển | D8: Hủy | E8: Fail

Sheet LogIn_DataTest
A1: Id TestCase | B1: STT | C1: Email | D1: Password | E1: Expected Result | F1: Result
A2: =Synthesis_TestCase!A25 | B2: 1 | C2: minhtam39@gmail.com | D2: YourSecurePassword | E2: Pass | F2: Pass
A3: =Synthesis_TestCase!A26 | B3: 2 | C3: tame@gmail.com | D3: 1234 | E3: Fail | F3: Pass
A4: =Synthesis_TestCase!A27 | B4: 3 | C4: minhtam | D4: 12356 | E4: Fail | F4: Fail
A5: =Synthesis_TestCase!A28 | B5: 4 | C5: minhtam@gmail.com | D5: minhtam | E5: Fail | F5: Pass
A6: =Synthesis_TestCase!A29 | B6: 5 | E6: Fail | F6: Fail
A7: =Synthesis_TestCase!A30 | B7: 6 | C7: minhtam!!@gmail.com | D7: YourSecurePassword | E7: Fail | F7: Pass | I7: 1
A8: =Synthesis_TestCase!A31 | B8: 7 | C8: minhtamne@gmail.com | D8: YourSecureP___assword | E8: Fail | F8: Pass
A9: =Synthesis_TestCase!A32 | B9: 8 | C9: minhta m@gmail.com | D9: YourSe curePassword | E9: Fail | F9: Fail

Sheet QLDH_Intergrates_DataTest
A1: Id TestCase | B1: ID Đơn hàng | C1: Trạng thái hiện tại | D1: Trạng thái mong muốn | E1: Result
A2: TC_IN_01 | B2: 79 | C2: Đang chờ | D2: Đang xử lý | F2: Fail
A3: TC_IN_02 | B3: 80 | C3: Đang chờ | D3: Hủy
